[2025-02-18 20:26:35,848] main.py:56 DEBUG    Бот запущен
[2025-02-18 20:26:35,934] main.py:19 DEBUG    Запуск бота
[2025-02-18 20:28:35,556] main.py:56 DEBUG    Бот запущен
[2025-02-18 20:28:35,560] main.py:19 DEBUG    Запуск бота
[2025-02-19 20:49:44,321] main.py:56 DEBUG    Бот запущен
[2025-02-19 20:49:44,410] main.py:19 DEBUG    Запуск бота
[2025-02-19 21:11:07,207] main.py:56 DEBUG    Бот запущен
[2025-02-19 21:11:07,212] main.py:19 DEBUG    Запуск бота
[2025-02-19 21:26:32,165] main.py:56 DEBUG    Бот запущен
[2025-02-19 21:26:32,169] main.py:19 DEBUG    Запуск бота
[2025-02-19 21:28:16,213] main.py:56 DEBUG    Бот запущен
[2025-02-19 21:28:16,224] main.py:19 DEBUG    Запуск бота
[2025-02-20 16:05:03,229] main.py:56 DEBUG    Бот запущен
[2025-02-20 16:05:03,252] main.py:19 DEBUG    Запуск бота
[2025-02-20 16:06:05,218] main.py:56 DEBUG    Бот запущен
[2025-02-20 16:06:05,224] main.py:19 DEBUG    Запуск бота
[2025-02-20 16:06:36,973] control_panel.py:1455 DEBUG    ❌ Не удалось проверить баланс индексации.

<b>Причина</b>: {"status":403,"msg":"Access denied: User not found","data":[]}
[2025-02-20 16:26:12,877] main.py:56 DEBUG    Бот запущен
[2025-02-20 16:26:12,882] main.py:19 DEBUG    Запуск бота
[2025-02-20 16:29:40,416] main.py:56 DEBUG    Бот запущен
[2025-02-20 16:29:40,421] main.py:19 DEBUG    Запуск бота
